Workbook

Sheet README
A1: Character Sheet
A3: A 5e character sheet with four house rules baked into the formulas. Edit the parchment-coloured cells; the lichen-blue cells are calculated and shouldn't be overwritten.
A5: House Rules
A6: Slot-based inventory | B6: Carrying capacity = Strength score, in slots. Each item has a slot cost; the Inventory sheet's capacity bar turns red if the pack goes over.
A7: Exhaustion 0-6 | B7: Each level applies -2 to all d20 tests and -5 ft to speed; at level 6 the character dies. Each level of exhaustion also occupies one inventory slot.
A8: Death Tally | B8: When the character hits 0 HP the GM rolls 1d4 in secret — the number of rounds before death. The Death Tally cell is for tables that prefer the count visible.
A9: Static HP from class + CON | B9: Max HP = HP-die maximum (by class) + Constitution modifier. Does not scale with level. Auto-computed once you select a class.
A10: DEX score = Initiative | B10: Initiative is the raw Dexterity score, not the modifier. (Not tracked as a separate field — read it off the DEX row.)
A11: Climb speed = half walking speed | B11: Climb Speed is auto-derived from Walking Speed. No separate input needed.
A13: Sheets
A14: Character | B14: Identity, ability scores, combat, homebrew trackers, skills.
A15: Inventory | B15: Slot-based pack with auto capacity bar.
A16: Combat & Spells | B16: Weapons / attacks, spellcasting block, auto-filled spell-slot grid, spells known.
A17: Features & Notes | B17: Class / racial / background features, languages, proficiencies, backstory.
A18: _ClassRef | B18: Hidden-friendly helper sheet: ClassDB and SlotTable. Edit only if you're adding homebrew classes.
A20: Colour Key
B21: Input cell — type here.
B22: Calculated — do not overwrite.
B23: Field label.
B24: House-rule field.
B25: Warning — over capacity / dying.

Sheet Character
A1: Character
A3: Character Name | E3: Class | G3: Level | H3: 1 | I3: Climb Speed | J3: =FLOOR(H5/2,1)
A4: Race / Ancestry | E4: Background | G4: Alignment | I4: Player
A5: Proficiency Bonus | B5: =IF(ISNUMBER($H$3),INT(($H$3-1)/4)+2,2) | C5: Inspiration | E5: Passive Perception | F5: =10+C13+IF(C40="✓",IF(D40="✓",2,1)*$B$5,0)-2*$A$24 | G5: Walking Speed | H5: 30 | I5: Effective Walk | J5: =MAX(0,H5-5*$A$24)
A7: Ability Scores & Saving Throws
A8: Ability | B8: Score | C8: Mod | D8: Save Prof? | E8: Save Total
A9: STR | B9: 10 | C9: =INT((B9-10)/2) | E9: =C9+IF(D9="✓",$B$5,0)-2*$A$24
A10: DEX | B10: 10 | C10: =INT((B10-10)/2) | E10: =C10+IF(D10="✓",$B$5,0)-2*$A$24
A11: CON | B11: 10 | C11: =INT((B11-10)/2) | E11: =C11+IF(D11="✓",$B$5,0)-2*$A$24
A12: INT | B12: 10 | C12: =INT((B12-10)/2) | E12: =C12+IF(D12="✓",$B$5,0)-2*$A$24
A13: WIS | B13: 10 | C13: =INT((B13-10)/2) | E13: =C13+IF(D13="✓",$B$5,0)-2*$A$24
A14: CHA | B14: 10 | C14: =INT((B14-10)/2) | E14: =C14+IF(D14="✓",$B$5,0)-2*$A$24
A15: Each level of exhaustion applies -2 to all d20 tests. The Save column already includes this.
A17: Combat & Hit Points
A18: AC | B18: Hit Dice (total) | C18: Max HP | D18: Current HP | E18: Temp HP
A19: 10 | C19: =IFERROR(XLOOKUP($F$3,ClassDB[Class],ClassDB[HitDieMax])+C11,0) | E19: 0
A20: House rule: Max HP = (Class HP-die maximum) + CON modifier. Auto-computed from class selection; does not scale with level.
A22: Homebrew Trackers
A23: Exhaustion (0-6) | B23: Death Tally | C23: STR Score | D23: Item Slots Used | E23: Total Slots Used | F23: Slots Free | G23: d20 Penalty | H23: Speed Penalty
A24: 0 | B24: 0 | C24: =B9 | D24: =Inventory!$C$4 | E24: =A24+D24 | F24: =C24-E24 | G24: =-2*A24 | H24: =-5*A24
A25: Slot Total = STR. Total Used = items + exhaustion. Slots Free turns red when it goes negative. Initiative = DEX score (read off the DEX row).
A27: Skills
A28: Skill | B28: Ability | C28: Prof? | D28: Expertise? | E28: Modifier | F28: Notes
A29: Acrobatics | B29: DEX | E29: =C10+IF(C29="✓",IF(D29="✓",2,1)*$B$5,0)-2*$A$24
A30: Animal Handling | B30: WIS | E30: =C13+IF(C30="✓",IF(D30="✓",2,1)*$B$5,0)-2*$A$24
A31: Arcana | B31: INT | E31: =C12+IF(C31="✓",IF(D31="✓",2,1)*$B$5,0)-2*$A$24
A32: Athletics | B32: STR | E32: =C9+IF(C32="✓",IF(D32="✓",2,1)*$B$5,0)-2*$A$24
A33: Deception | B33: CHA | E33: =C14+IF(C33="✓",IF(D33="✓",2,1)*$B$5,0)-2*$A$24
A34: History | B34: INT | E34: =C12+IF(C34="✓",IF(D34="✓",2,1)*$B$5,0)-2*$A$24
A35: Insight | B35: WIS | E35: =C13+IF(C35="✓",IF(D35="✓",2,1)*$B$5,0)-2*$A$24
A36: Intimidation | B36: CHA | E36: =C14+IF(C36="✓",IF(D36="✓",2,1)*$B$5,0)-2*$A$24
A37: Investigation | B37: INT | E37: =C12+IF(C37="✓",IF(D37="✓",2,1)*$B$5,0)-2*$A$24
A38: Medicine | B38: WIS | E38: =C13+IF(C38="✓",IF(D38="✓",2,1)*$B$5,0)-2*$A$24
A39: Nature | B39: INT | E39: =C12+IF(C39="✓",IF(D39="✓",2,1)*$B$5,0)-2*$A$24
A40: Perception | B40: WIS | E40: =C13+IF(C40="✓",IF(D40="✓",2,1)*$B$5,0)-2*$A$24
A41: Performance | B41: CHA | E41: =C14+IF(C41="✓",IF(D41="✓",2,1)*$B$5,0)-2*$A$24
A42: Persuasion | B42: CHA | E42: =C14+IF(C42="✓",IF(D42="✓",2,1)*$B$5,0)-2*$A$24
A43: Religion | B43: INT | E43: =C12+IF(C43="✓",IF(D43="✓",2,1)*$B$5,0)-2*$A$24
A44: Sleight of Hand | B44: DEX | E44: =C10+IF(C44="✓",IF(D44="✓",2,1)*$B$5,0)-2*$A$24
A45: Stealth | B45: DEX | E45: =C10+IF(C45="✓",IF(D45="✓",2,1)*$B$5,0)-2*$A$24
...

Sheet Inventory
A1: Inventory
A3: STR Slots | B3: Exhaustion Slots | C3: Item Slots Used | D3: Total Used | E3: Free
A4: =Character!B9 | B4: =Character!$A$24 | C4: =SUM($C$9:$C$58) | D4: =B4+C4 | E4: =A4-D4
A5: Each level of exhaustion auto-occupies one slot. Set the Slot Cost for each item; the capacity bar reddens when total used exceeds STR.
A7: Items
A8: # | B8: Item | C8: Slot Cost | D8: Qty | E8: Notes
A9: 1
A10: 2
A11: 3
A12: 4
A13: 5
A14: 6
A15: 7
A16: 8
A17: 9
A18: 10
A19: 11
A20: 12
... A58: 50

Sheet Combat & Spells
A1: Combat & Spells
A3: Weapons & Attacks
A4: Name | B4: Ability | C4: Prof? | D4: Attack Bonus | E4: Damage | F4: Range | G4: Type | H4: Ammo / Uses | I4: Notes
A17: Spellcasting
A18: Spellcasting Class | B18: Spell Ability | C18: Spell Save DC | D18: Spell Attack Bonus | E18: Ritual? | F18: Concentration? | G18: Notes
A20: Spell Save DC = 8 + Proficiency Bonus + Spellcasting Ability modifier. Spell Attack Bonus = Proficiency Bonus + Spellcasting Ability modifier.
A22: Spell Slots
A23: Level | B23: 1st | C23: 2nd | D23: 3rd | E23: 4th | F23: 5th | G23: 6th | H23: 7th | I23: 8th | J23: 9th
A24: Slots (auto) | B24: =IFERROR(INDEX(FILTER(SlotTable[Slots1],(SlotTable[Class]=Character!$F$3)*(SlotTable[Lvl]=Character!$H$3)),1),0) | C24: =IFERROR(INDEX(FILTER(SlotTable[Slots2],(SlotTable[Class]=Character!$F$3)*(SlotTable[Lvl]=Character!$H$3)),1),0) | D24: =IFERROR(INDEX(FILTER(SlotTable[Slots3],(SlotTable[Class]=Character!$F$3)*(SlotTable[Lvl]=Character!$H$3)),1),0) | E24: =IFERROR(INDEX(FILTER(SlotTable[Slots4],(SlotTable[Class]=Character!$F$3)*(SlotTable[Lvl]=Character!$H$3)),1),0) | F24: =IFERROR(INDEX(FILTER(SlotTable[Slots5],(SlotTable[Class]=Character!$F$3)*(SlotTable[Lvl]=Character!$H$3)),1),0) | G24: =IFERROR(INDEX(FILTER(SlotTable[Slots6],(SlotTable[Class]=Character!$F$3)*(SlotTable[Lvl]=Character!$H$3)),1),0) | H24: =IFERROR(INDEX(FILTER(SlotTable[Slots7],(SlotTable[Class]=Character!$F$3)*(SlotTable[Lvl]=Character!$H$3)),1),0) | I24: =IFERROR(INDEX(FILTER(SlotTable[Slots8],(SlotTable[Class]=Character!$F$3)*(SlotTable[Lvl]=Character!$H$3)),1),0) | J24: =IFERROR(INDEX(FILTER(SlotTable[Slots9],(SlotTable[Class]=Character!$F$3)*(SlotTable[Lvl]=Character!$H$3)),1),0)
A25: Used | B25: 0 | C25: 0 | D25: 0 | E25: 0 | F25: 0 | G25: 0 | H25: 0 | I25: 0 | J25: 0
A26: Remaining | B26: =MAX(0,B24-B25) | C26: =MAX(0,C24-C25) | D26: =MAX(0,D24-D25) | E26: =MAX(0,E24-E25) | F26: =MAX(0,F24-F25) | G26: =MAX(0,G24-G25) | H26: =MAX(0,H24-H25) | I26: =MAX(0,I24-I25) | J26: =MAX(0,J24-J25)
A27: Display | B27: =IF(B24=0,"—",TRIM(REPT("○ ",B26)&REPT("● ",MIN(B25,B24)))) | C27: =IF(C24=0,"—",TRIM(REPT("○ ",C26)&REPT("● ",MIN(C25,C24)))) | D27: =IF(D24=0,"—",TRIM(REPT("○ ",D26)&REPT("● ",MIN(D25,D24)))) | E27: =IF(E24=0,"—",TRIM(REPT("○ ",E26)&REPT("● ",MIN(E25,E24)))) | F27: =IF(F24=0,"—",TRIM(REPT("○ ",F26)&REPT("● ",MIN(F25,F24)))) | G27: =IF(G24=0,"—",TRIM(REPT("○ ",G26)&REPT("● ",MIN(G25,G24)))) | H27: =IF(H24=0,"—",TRIM(REPT("○ ",H26)&REPT("● ",MIN(H25,H24)))) | I27: =IF(I24=0,"—",TRIM(REPT("○ ",I26)&REPT("● ",MIN(I25,I24)))) | J27: =IF(J24=0,"—",TRIM(REPT("○ ",J26)&REPT("● ",MIN(J25,J24))))
A29: Spells Known & Prepared
A30: Spell | B30: Level | C30: School | D30: Cast Time | E30: Range | F30: Components | G30: Duration | H30: Prepared? | I30: Notes

Sheet Features & Notes
A1: Features & Notes
A3: Class Features
A12: Racial / Ancestry Features
A19: Background Feature
A22: Feats
A27: Languages
A31: Other Proficiencies (tools, instruments, etc.)
A36: Allies & Contacts
A41: Backstory
A48: Session Notes

Sheet _ClassRef
A1: Class | B1: HitDie | C1: HitDieMax | D1: CasterType | F1: Class | G1: Lvl | H1: Slots1 | I1: Slots2 | J1: Slots3 | K1: Slots4 | L1: Slots5 | M1: Slots6 | N1: Slots7 | O1: Slots8 | P1: Slots9
A2: Artificer | B2: d8 | C2: 8 | D2: Half | F2: Artificer | G2: 1 | H2: 2 | I2: 0 | J2: 0 | K2: 0 | L2: 0 | M2: 0 | N2: 0 | O2: 0 | P2: 0
A3: Barbarian | B3: d12 | C3: 12 | D3: None | F3: Artificer | G3: 2 | H3: 2 | I3: 0 | J3: 0 | K3: 0 | L3: 0 | M3: 0 | N3: 0 | O3: 0 | P3: 0
A4: Bard | B4: d8 | C4: 8 | D4: Full | F4: Artificer | G4: 3 | H4: 3 | I4: 0 | J4: 0 | K4: 0 | L4: 0 | M4: 0 | N4: 0 | O4: 0 | P4: 0
A5: Cleric | B5: d8 | C5: 8 | D5: Full | F5: Artificer | G5: 4 | H5: 3 | I5: 0 | J5: 0 | K5: 0 | L5: 0 | M5: 0 | N5: 0 | O5: 0 | P5: 0
A6: Druid | B6: d8 | C6: 8 | D6: Full | F6: Artificer | G6: 5 | H6: 4 | I6: 2 | J6: 0 | K6: 0 | L6: 0 | M6: 0 | N6: 0 | O6: 0 | P6: 0
A7: Fighter | B7: d10 | C7: 10 | D7: None | F7: Artificer | G7: 6 | H7: 4 | I7: 2 | J7: 0 | K7: 0 | L7: 0 | M7: 0 | N7: 0 | O7: 0 | P7: 0
A8: Monk | B8: d8 | C8: 8 | D8: None | F8: Artificer | G8: 7 | H8: 4 | I8: 3 | J8: 0 | K8: 0 | L8: 0 | M8: 0 | N8: 0 | O8: 0 | P8: 0
A9: Paladin | B9: d10 | C9: 10 | D9: Half | F9: Artificer | G9: 8 | H9: 4 | I9: 3 | J9: 0 | K9: 0 | L9: 0 | M9: 0 | N9: 0 | O9: 0 | P9: 0
A10: Ranger | B10: d10 | C10: 10 | D10: Half | F10: Artificer | G10: 9 | H10: 4 | I10: 3 | J10: 2 | K10: 0 | L10: 0 | M10: 0 | N10: 0 | O10: 0 | P10: 0
A11: Rogue | B11: d8 | C11: 8 | D11: None | F11: Artificer | G11: 10 | H11: 4 | I11: 3 | J11: 2 | K11: 0 | L11: 0 | M11: 0 | N11: 0 | O11: 0 | P11: 0
A12: Sorcerer | B12: d6 | C12: 6 | D12: Full | F12: Artificer | G12: 11 | H12: 4 | I12: 3 | J12: 3 | K12: 0 | L12: 0 | M12: 0 | N12: 0 | O12: 0 | P12: 0
A13: Warlock | B13: d8 | C13: 8 | D13: Pact | F13: Artificer | G13: 12 | H13: 4 | I13: 3 | J13: 3 | K13: 0 | L13: 0 | M13: 0 | N13: 0 | O13: 0 | P13: 0
A14: Wizard | B14: d6 | C14: 6 | D14: Full | F14: Artificer | G14: 13 | H14: 4 | I14: 3 | J14: 3 | K14: 1 | L14: 0 | M14: 0 | N14: 0 | O14: 0 | P14: 0
F15: Artificer | G15: 14 | H15: 4 | I15: 3 | J15: 3 | K15: 1 | L15: 0 | M15: 0 | N15: 0 | O15: 0 | P15: 0
F16: Artificer | G16: 15 | H16: 4 | I16: 3 | J16: 3 | K16: 2 | L16: 0 | M16: 0 | N16: 0 | O16: 0 | P16: 0
F17: Artificer | G17: 16 | H17: 4 | I17: 3 | J17: 3 | K17: 2 | L17: 0 | M17: 0 | N17: 0 | O17: 0 | P17: 0
F18: Artificer | G18: 17 | H18: 4 | I18: 3 | J18: 3 | K18: 3 | L18: 1 | M18: 0 | N18: 0 | O18: 0 | P18: 0
F19: Artificer | G19: 18 | H19: 4 | I19: 3 | J19: 3 | K19: 3 | L19: 1 | M19: 0 | N19: 0 | O19: 0 | P19: 0
F20: Artificer | G20: 19 | H20: 4 | I20: 3 | J20: 3 | K20: 3 | L20: 2 | M20: 0 | N20: 0 | O20: 0 | P20: 0
F21: Artificer | G21: 20 | H21: 4 | I21: 3 | J21: 3 | K21: 3 | L21: 2 | M21: 0 | N21: 0 | O21: 0 | P21: 0
F22: Barbarian | G22: 1 | H22: 0 | I22: 0 | J22: 0 | K22: 0 | L22: 0 | M22: 0 | N22: 0 | O22: 0 | P22: 0
F23: Barbarian | G23: 2 | H23: 0 | I23: 0 | J23: 0 | K23: 0 | L23: 0 | M23: 0 | N23: 0 | O23: 0 | P23: 0
F24: Barbarian | G24: 3 | H24: 0 | I24: 0 | J24: 0 | K24: 0 | L24: 0 | M24: 0 | N24: 0 | O24: 0 | P24: 0
F25: Barbarian | G25: 4 | H25: 0 | I25: 0 | J25: 0 | K25: 0 | L25: 0 | M25: 0 | N25: 0 | O25: 0 | P25: 0
F26: Barbarian | G26: 5 | H26: 0 | I26: 0 | J26: 0 | K26: 0 | L26: 0 | M26: 0 | N26: 0 | O26: 0 | P26: 0
... F261: Wizard | G261: 20 | H261: 4 | I261: 3 | J261: 3 | K261: 3 | L261: 3 | M261: 2 | N261: 2 | O261: 1 | P261: 1
